<sdf version='1.7'>
  <world name='default'>
    <light name='sun' type='directional'>
      <cast_shadows>1</cast_shadows>
      <pose>0 0 10 0 -0 0</pose>
      <diffuse>0.8 0.8 0.8 1</diffuse>
      <specular>0.2 0.2 0.2 1</specular>
      <attenuation>
        <range>1000</range>
        <constant>0.9</constant>
        <linear>0.01</linear>
        <quadratic>0.001</quadratic>
      </attenuation>
      <direction>-0.5 0.1 -0.9</direction>
      <spot>
        <inner_angle>0</inner_angle>
        <outer_angle>0</outer_angle>
        <falloff>0</falloff>
      </spot>
    </light>
    <model name='ground_plane'>
      <static>1</static>
      <link name='link'>
        <collision name='collision'>
          <geometry>
            <plane>
              <normal>0 0 1</normal>
              <size>100 100</size>
            </plane>
          </geometry>
          <surface>
            <friction>
              <ode>
                <mu>100</mu>
                <mu2>50</mu2>
              </ode>
              <torsional>
                <ode/>
              </torsional>
            </friction>
            <contact>
              <ode/>
            </contact>
            <bounce/>
          </surface>
          <max_contacts>10</max_contacts>
        </collision>
        <visual name='visual'>
          <cast_shadows>0</cast_shadows>
          <geometry>
            <plane>
              <normal>0 0 1</normal>
              <size>100 100</size>
            </plane>
          </geometry>
          <material>
            <script>
              <uri>file://media/materials/scripts/gazebo.material</uri>
              <name>Gazebo/Grey</name>
            </script>
          </material>
        </visual>
        <self_collide>0</self_collide>
        <enable_wind>0</enable_wind>
        <kinematic>0</kinematic>
      </link>
    </model>
    <gravity>0 0 -9.8</gravity>
    <magnetic_field>6e-06 2.3e-05 -4.2e-05</magnetic_field>
    <atmosphere type='adiabatic'/>
    <physics type='ode'>
      <max_step_size>0.001</max_step_size>
      <real_time_factor>1</real_time_factor>
      <real_time_update_rate>1000</real_time_update_rate>
    </physics>
    <scene>
      <ambient>0.4 0.4 0.4 1</ambient>
      <background>0.7 0.7 0.7 1</background>
      <shadows>1</shadows>
    </scene>
    <audio>
      <device>default</device>
    </audio>
    <wind/>
    <spherical_coordinates>
      <surface_model>EARTH_WGS84</surface_model>
      <latitude_deg>0</latitude_deg>
      <longitude_deg>0</longitude_deg>
      <elevation>0</elevation>
      <heading_deg>0</heading_deg>
    </spherical_coordinates>
    <state world_name='default'>
      <sim_time>1696 825000000</sim_time>
      <real_time>278 902007530</real_time>
      <wall_time>1716643345 654686135</wall_time>
      <iterations>191342</iterations>
      <model name='grey_wall'>
        <pose>-1.2838 2.09311 0 0 -0 0</pose>
        <scale>1 1 1</scale>
        <link name='link'>
          <pose>-1.2838 2.09311 1.4 0 -0 0</pose>
          <velocity>0 0 0 0 -0 0</velocity>
          <acceleration>0 0 0 0 -0 0</acceleration>
          <wrench>0 0 0 0 -0 0</wrench>
        </link>
      </model>
      <model name='grey_wall_0'>
        <pose>-1.25342 -5.00541 0 0 -0 0</pose>
        <scale>1 1 1</scale>
        <link name='link'>
          <pose>-1.25342 -5.00541 1.4 0 -0 0</pose>
          <velocity>0 0 0 0 -0 0</velocity>
          <acceleration>0 0 0 0 -0 0</acceleration>
          <wrench>0 0 0 0 -0 0</wrench>
        </link>
      </model>
      <model name='grey_wall_1'>
        <pose>-6.1399 -1.50385 0 0 -0 1.55832</pose>
        <scale>1 1 1</scale>
        <link name='link'>
          <pose>-6.1399 -1.50385 1.4 0 -0 1.55832</pose>
          <velocity>0 0 0 0 -0 0</velocity>
          <acceleration>0 0 0 0 -0 0</acceleration>
          <wrench>0 0 0 0 -0 0</wrench>
        </link>
      </model>
      <model name='grey_wall_2'>
        <pose>2.63788 -1.36924 0 0 0 -1.59938</pose>
        <scale>1 1 1</scale>
        <link name='link'>
          <pose>2.63788 -1.36924 1.4 0 0 -1.59938</pose>
          <velocity>0 0 0 0 -0 0</velocity>
          <acceleration>0 0 0 0 -0 0</acceleration>
          <wrench>0 0 0 0 -0 0</wrench>
        </link>
      </model>
      <model name='ground_plane'>
        <pose>0 0 0 0 -0 0</pose>
        <scale>1 1 1</scale>
        <link name='link'>
          <pose>0 0 0 0 -0 0</pose>
          <velocity>0 0 0 0 -0 0</velocity>
          <acceleration>0 0 0 0 -0 0</acceleration>
          <wrench>0 0 0 0 -0 0</wrench>
        </link>
      </model>
      <model name='linorobot2'>
        <pose>-5.14289 -1.51846 1e-06 0 -0 0.019894</pose>
        <scale>1 1 1</scale>
        <link name='base_footprint'>
          <pose>-5.14289 -1.51846 1e-06 0 -0 0.019894</pose>
          <velocity>1.5e-05 1e-06 -2e-06 1e-06 -0 0</velocity>
          <acceleration>0 -0 6e-06 -2e-06 0 0</acceleration>
          <wrench>1e-06 -2e-06 6.4e-05 0 -0 0</wrench>
        </link>
        <link name='front_left_wheel_link'>
          <pose>-5.02561 -1.3806 0.071621 -3.14153 -0.944521 -3.12175</pose>
          <velocity>1.5e-05 4e-06 -2e-06 0.000107 0.000215 0</velocity>
          <acceleration>0 -9e-06 6e-06 -0.000318 -1e-05 0</acceleration>
          <wrench>0 -6e-06 4e-06 0 -0 0</wrench>
        </link>
        <link name='front_right_wheel_link'>
          <pose>-5.02022 -1.65154 0.071621 3.8e-05 -0.08962 0.01989</pose>
          <velocity>1.6e-05 -3e-06 -2e-06 -0.000115 0.000208 0</velocity>
          <acceleration>-0 9e-06 6e-06 0.000317 9e-06 1e-06</acceleration>
          <wrench>-0 5e-06 4e-06 0 -0 0</wrench>
        </link>
        <link name='rear_left_wheel_link'>
          <pose>-5.26556 -1.38537 0.071621 -3.14144 -1.31074 -3.12185</pose>
          <velocity>1.5e-05 4e-06 -2e-06 0.000108 0.000213 0</velocity>
          <acceleration>0 -9e-06 6e-06 -0.000322 -6e-06 0</acceleration>
          <wrench>0 -6e-06 4e-06 0 -0 0</wrench>
        </link>
        <link name='rear_right_wheel_link'>
          <pose>-5.26017 -1.65632 0.071621 3.14148 1.1952 -3.1218</pose>
          <velocity>1.6e-05 -3e-06 -2e-06 -0.000117 0.000208 0</velocity>
          <acceleration>-0 9e-06 6e-06 0.000322 8e-06 -2e-06</acceleration>
          <wrench>-0 6e-06 4e-06 0 -0 0</wrench>
        </link>
      </model>
      <light name='sun'>
        <pose>0 0 10 0 -0 0</pose>
      </light>
    </state>
    <gui fullscreen='0'>
      <camera name='user_camera'>
        <pose>-13.5536 0.068418 18.4017 0 0.994121 -0.146214</pose>
        <view_controller>orbit</view_controller>
        <projection_type>perspective</projection_type>
      </camera>
    </gui>
    <model name='linorobot2'>
      <link name='base_footprint'>
        <inertial>
          <pose>0.001683 0 0.122883 0 -0 0</pose>
          <mass>10.235</mass>
          <inertia>
            <ixx>0.0561018</ixx>
            <ixy>0</ixy>
            <ixz>0.0022439</ixz>
            <iyy>0.194928</iyy>
            <iyz>0</iyz>
            <izz>0.205895</izz>
          </inertia>
        </inertial>
        <collision name='base_footprint_fixed_joint_lump__base_link_collision'>
          <pose>0 0 0.1195 0 -0 0</pose>
          <geometry>
            <box>
              <size>0.445 0.2 0.129</size>
            </box>
          </geometry>
          <surface>
            <contact>
              <ode/>
            </contact>
            <friction>
              <ode/>
              <torsional>
                <ode/>
              </torsional>
            </friction>
            <bounce/>
          </surface>
          <max_contacts>10</max_contacts>
        </collision>
        <collision name='base_footprint_fixed_joint_lump__camera_link_collision_1'>
          <pose>-0.065 0 0.3745 0 -0 0</pose>
          <geometry>
            <box>
              <size>0.03 0.124 0.03</size>
            </box>
          </geometry>
          <surface>
            <contact>
              <ode/>
            </contact>
            <friction>
              <ode/>
              <torsional>
                <ode/>
              </torsional>
            </friction>
            <bounce/>
          </surface>
          <max_contacts>10</max_contacts>
        </collision>
        <collision name='base_footprint_fixed_joint_lump__laser_collision_2'>
          <pose>0.26 0 0.0965 0 -0 0</pose>
          <geometry>
            <cylinder>
              <length>0.05</length>
              <radius>0.0375</radius>
            </cylinder>
          </geometry>
          <surface>
            <contact>
              <ode/>
            </contact>
            <friction>
              <ode/>
              <torsional>
                <ode/>
              </torsional>
            </friction>
            <bounce/>
          </surface>
          <max_contacts>10</max_contacts>
        </collision>
        <visual name='base_footprint_fixed_joint_lump__base_link_visual'>
          <pose>0 0 0.1195 0 -0 0</pose>
          <geometry>
            <box>
              <size>0.445 0.2 0.129</size>
            </box>
          </geometry>
          <material>
            <ambient>0.8392 0.6314 0 1</ambient>
            <diffuse>0.8392 0.6314 0 1</diffuse>
            <specular>0.99 0.99 0.99 1</specular>
            <emissive>0 0 0 0</emissive>
          </material>
        </visual>
        <visual name='base_footprint_fixed_joint_lump__camera_link_visual_1'>
          <pose>-0.065 0 0.3745 0 -0 0</pose>
          <geometry>
            <box>
              <size>0.03 0.124 0.03</size>
            </box>
          </geometry>
          <material>
            <ambient>0.416 0.051 0.047 1</ambient>
            <diffuse>0.416 0.051 0.047 1</diffuse>
            <specular>0.416 0.051 0.047 1</specular>
            <emissive>0.416 0.051 0.047 1</emissive>
          </material>
        </visual>
        <visual name='base_footprint_fixed_joint_lump__laser_visual_2'>
          <pose>0.26 0 0.0965 0 -0 0</pose>
          <geometry>
            <cylinder>
              <length>0.05</length>
              <radius>0.0375</radius>
            </cylinder>
          </geometry>
          <material>
            <ambient>0.003 0.639 0.223 1</ambient>
            <diffuse>0.003 0.639 0.223 1</diffuse>
            <specular>0.003 0.639 0.223 1</specular>
            <emissive>0 0 0 0</emissive>
          </material>
        </visual>
        <sensor name='camera' type='depth'>
          <always_on>1</always_on>
          <update_rate>30</update_rate>
          <camera name='camera'>
            <horizontal_fov>1.50098</horizontal_fov>
            <image>
              <width>640</width>
              <height>480</height>
              <format>R8G8B8</format>
            </image>
            <clip>
              <near>0.1</near>
              <far>100</far>
            </clip>
          </camera>
          <plugin name='camera_controller' filename='libgazebo_ros_camera.so'>
            <ros>
              <remapping>/camera/camera_info:=/camera/color/camera_info</remapping>
              <remapping>/camera/image_raw:=/camera/color/image_raw</remapping>
              <remapping>/camera/points:=/camera/depth/color/points</remapping>
              <remapping>/camera/depth/image_raw:=/camera/depth/image_rect_raw</remapping>
              <qos>
                <topic name='/camera/depth/color/points'>
                  <publisher>
                    <reliability>best_effort</reliability>
                  </publisher>
                </topic>
              </qos>
            </ros>
            <min_depth>0.015</min_depth>
            <max_depth>3.0</max_depth>
            <hack_baseline>0.07</hack_baseline>
            <frame_name>camera_depth_link</frame_name>
            <distortion_k1>0.00000001</distortion_k1>
            <distortion_k2>0.00000001</distortion_k2>
            <distortion_k3>0.00000001</distortion_k3>
            <distortion_t1>0.00000001</distortion_t1>
            <distortion_t2>0.00000001</distortion_t2>
          </plugin>
          <pose>-0.065 0 0.3745 0 -0 0</pose>
        </sensor>
        <gravity>1</gravity>
        <sensor name='imu_sensor' type='imu'>
          <always_on>1</always_on>
          <update_rate>20</update_rate>
          <visualize>1</visualize>
          <topic>__default_topic__</topic>
          <plugin name='imu_plugin' filename='libgazebo_ros_imu_sensor.so'>
            <ros>
              <remapping>~/out:=imu/data</remapping>
            </ros>
            <topicName>imu/data</topicName>
            <bodyName>imu_link</bodyName>
            <updateRateHZ>10.0</updateRateHZ>
            <gaussianNoise>0.0</gaussianNoise>
            <xyzOffset>0 0 0</xyzOffset>
            <rpyOffset>0 0 0</rpyOffset>
            <frameName>imu_link</frameName>
            <initialOrientationAsReference>0</initialOrientationAsReference>
          </plugin>
          <pose>0 0 0.1195 0 -0 0</pose>
          <imu/>
        </sensor>
        <sensor name='laser_lidar' type='gpu_ray'>
          <always_on>1</always_on>
          <update_rate>10</update_rate>
          <visualize>1</visualize>
          <ray>
            <scan>
              <horizontal>
                <samples>360</samples>
                <resolution>1</resolution>
                <min_angle>-1.5716</min_angle>
                <max_angle>1.5716</max_angle>
              </horizontal>
              <vertical>
                <samples>1</samples>
                <min_angle>0</min_angle>
                <max_angle>0</max_angle>
              </vertical>
            </scan>
            <range>
              <min>0.08</min>
              <max>6</max>
              <resolution>0.01</resolution>
            </range>
          </ray>
          <plugin name='laser_lidar_controller' filename='libgazebo_ros_ray_sensor.so'>
            <ros>
              <remapping>~/out:=scan</remapping>
            </ros>
            <output_type>sensor_msgs/LaserScan</output_type>
            <alwaysOn>1</alwaysOn>
            <updateRate>10</updateRate>
            <topicName>scan</topicName>
            <frame_name>laser</frame_name>
            <output_type>sensor_msgs/LaserScan</output_type>
          </plugin>
          <pose>0.26 0 0.1215 0 -0 0</pose>
        </sensor>
        <self_collide>0</self_collide>
        <enable_wind>0</enable_wind>
        <kinematic>0</kinematic>
      </link>
      <joint name='front_left_wheel_joint' type='revolute'>
        <pose relative_to='base_footprint'>0.12 0.1355 0.07162 0 -0 0</pose>
        <parent>base_footprint</parent>
        <child>front_left_wheel_link</child>
        <axis>
          <xyz>0 1 0</xyz>
          <limit>
            <lower>-1e+16</lower>
            <upper>1e+16</upper>
          </limit>
          <dynamics>
            <spring_reference>0</spring_reference>
            <spring_stiffness>0</spring_stiffness>
          </dynamics>
        </axis>
      </joint>
      <link name='front_left_wheel_link'>
        <pose relative_to='front_left_wheel_joint'>0 0 0 0 -0 0</pose>
        <inertial>
          <pose>0 0 0 0 -0 0</pose>
          <mass>0.6</mass>
          <inertia>
            <ixx>0.00123106</ixx>
            <ixy>0</ixy>
            <ixz>0</ixz>
            <iyy>0.00123106</iyy>
            <iyz>0</iyz>
            <izz>0.00123106</izz>
          </inertia>
        </inertial>
        <collision name='front_left_wheel_link_collision'>
          <pose>0 0 0 1.5708 -0 0</pose>
          <geometry>
            <cylinder>
              <length>0.05</length>
              <radius>0.07162</radius>
            </cylinder>
          </geometry>
          <surface>
            <contact>
              <ode/>
            </contact>
            <friction>
              <ode/>
              <torsional>
                <ode/>
              </torsional>
            </friction>
            <bounce/>
          </surface>
          <max_contacts>10</max_contacts>
        </collision>
        <visual name='front_left_wheel_link_visual'>
          <pose>0 0 0 1.5708 -0 0</pose>
          <geometry>
            <cylinder>
              <length>0.05</length>
              <radius>0.07162</radius>
            </cylinder>
          </geometry>
          <material>
            <ambient>0.1764 0.4588 0.8509 1</ambient>
            <diffuse>0.1764 0.4588 0.8509 1</diffuse>
            <specular>0.1764 0.4588 0.8509 1</specular>
            <emissive>0 0 0 0</emissive>
          </material>
        </visual>
        <self_collide>0</self_collide>
        <enable_wind>0</enable_wind>
        <kinematic>0</kinematic>
      </link>
      <joint name='front_right_wheel_joint' type='revolute'>
        <pose relative_to='base_footprint'>0.12 -0.1355 0.07162 0 -0 0</pose>
        <parent>base_footprint</parent>
        <child>front_right_wheel_link</child>
        <axis>
          <xyz>0 1 0</xyz>
          <limit>
            <lower>-1e+16</lower>
            <upper>1e+16</upper>
          </limit>
          <dynamics>
            <spring_reference>0</spring_reference>
            <spring_stiffness>0</spring_stiffness>
          </dynamics>
        </axis>
      </joint>
      <link name='front_right_wheel_link'>
        <pose relative_to='front_right_wheel_joint'>0 0 0 0 -0 0</pose>
        <inertial>
          <pose>0 0 0 0 -0 0</pose>
          <mass>0.6</mass>
          <inertia>
            <ixx>0.00123106</ixx>
            <ixy>0</ixy>
            <ixz>0</ixz>
            <iyy>0.00123106</iyy>
            <iyz>0</iyz>
            <izz>0.00123106</izz>
          </inertia>
        </inertial>
        <collision name='front_right_wheel_link_collision'>
          <pose>0 0 0 1.5708 -0 0</pose>
          <geometry>
            <cylinder>
              <length>0.05</length>
              <radius>0.07162</radius>
            </cylinder>
          </geometry>
          <surface>
            <contact>
              <ode/>
            </contact>
            <friction>
              <ode/>
              <torsional>
                <ode/>
              </torsional>
            </friction>
            <bounce/>
          </surface>
          <max_contacts>10</max_contacts>
        </collision>
        <visual name='front_right_wheel_link_visual'>
          <pose>0 0 0 1.5708 -0 0</pose>
          <geometry>
            <cylinder>
              <length>0.05</length>
              <radius>0.07162</radius>
            </cylinder>
          </geometry>
          <material>
            <ambient>0.1764 0.4588 0.8509 1</ambient>
            <diffuse>0.1764 0.4588 0.8509 1</diffuse>
            <specular>0.1764 0.4588 0.8509 1</specular>
            <emissive>0 0 0 0</emissive>
          </material>
        </visual>
        <self_collide>0</self_collide>
        <enable_wind>0</enable_wind>
        <kinematic>0</kinematic>
      </link>
      <joint name='rear_left_wheel_joint' type='revolute'>
        <pose relative_to='base_footprint'>-0.12 0.1355 0.07162 0 -0 0</pose>
        <parent>base_footprint</parent>
        <child>rear_left_wheel_link</child>
        <axis>
          <xyz>0 1 0</xyz>
          <limit>
            <lower>-1e+16</lower>
            <upper>1e+16</upper>
          </limit>
          <dynamics>
            <spring_reference>0</spring_reference>
            <spring_stiffness>0</spring_stiffness>
          </dynamics>
        </axis>
      </joint>
      <link name='rear_left_wheel_link'>
        <pose relative_to='rear_left_wheel_joint'>0 0 0 0 -0 0</pose>
        <inertial>
          <pose>0 0 0 0 -0 0</pose>
          <mass>0.6</mass>
          <inertia>
            <ixx>0.00123106</ixx>
            <ixy>0</ixy>
            <ixz>0</ixz>
            <iyy>0.00123106</iyy>
            <iyz>0</iyz>
            <izz>0.00123106</izz>
          </inertia>
        </inertial>
        <collision name='rear_left_wheel_link_collision'>
          <pose>0 0 0 1.5708 -0 0</pose>
          <geometry>
            <cylinder>
              <length>0.05</length>
              <radius>0.07162</radius>
            </cylinder>
          </geometry>
          <surface>
            <contact>
              <ode/>
            </contact>
            <friction>
              <ode/>
              <torsional>
                <ode/>
              </torsional>
            </friction>
            <bounce/>
          </surface>
          <max_contacts>10</max_contacts>
        </collision>
        <visual name='rear_left_wheel_link_visual'>
          <pose>0 0 0 1.5708 -0 0</pose>
          <geometry>
            <cylinder>
              <length>0.05</length>
              <radius>0.07162</radius>
            </cylinder>
          </geometry>
          <material>
            <ambient>0.1764 0.4588 0.8509 1</ambient>
            <diffuse>0.1764 0.4588 0.8509 1</diffuse>
            <specular>0.1764 0.4588 0.8509 1</specular>
            <emissive>0 0 0 0</emissive>
          </material>
        </visual>
        <self_collide>0</self_collide>
        <enable_wind>0</enable_wind>
        <kinematic>0</kinematic>
      </link>
      <joint name='rear_right_wheel_joint' type='revolute'>
        <pose relative_to='base_footprint'>-0.12 -0.1355 0.07162 0 -0 0</pose>
        <parent>base_footprint</parent>
        <child>rear_right_wheel_link</child>
        <axis>
          <xyz>0 1 0</xyz>
          <limit>
            <lower>-1e+16</lower>
            <upper>1e+16</upper>
          </limit>
          <dynamics>
            <spring_reference>0</spring_reference>
            <spring_stiffness>0</spring_stiffness>
          </dynamics>
        </axis>
      </joint>
      <link name='rear_right_wheel_link'>
        <pose relative_to='rear_right_wheel_joint'>0 0 0 0 -0 0</pose>
        <inertial>
          <pose>0 0 0 0 -0 0</pose>
          <mass>0.6</mass>
          <inertia>
            <ixx>0.00123106</ixx>
            <ixy>0</ixy>
            <ixz>0</ixz>
            <iyy>0.00123106</iyy>
            <iyz>0</iyz>
            <izz>0.00123106</izz>
          </inertia>
        </inertial>
        <collision name='rear_right_wheel_link_collision'>
          <pose>0 0 0 1.5708 -0 0</pose>
          <geometry>
            <cylinder>
              <length>0.05</length>
              <radius>0.07162</radius>
            </cylinder>
          </geometry>
          <surface>
            <contact>
              <ode/>
            </contact>
            <friction>
              <ode/>
              <torsional>
                <ode/>
              </torsional>
            </friction>
            <bounce/>
          </surface>
          <max_contacts>10</max_contacts>
        </collision>
        <visual name='rear_right_wheel_link_visual'>
          <pose>0 0 0 1.5708 -0 0</pose>
          <geometry>
            <cylinder>
              <length>0.05</length>
              <radius>0.07162</radius>
            </cylinder>
          </geometry>
          <material>
            <ambient>0.1764 0.4588 0.8509 1</ambient>
            <diffuse>0.1764 0.4588 0.8509 1</diffuse>
            <specular>0.1764 0.4588 0.8509 1</specular>
            <emissive>0 0 0 0</emissive>
          </material>
        </visual>
        <self_collide>0</self_collide>
        <enable_wind>0</enable_wind>
        <kinematic>0</kinematic>
      </link>
      <static>0</static>
      <plugin name='differential_drive_controller' filename='libgazebo_ros_diff_drive.so'>
        <ros>
          <remapping>odom:=odom/unfiltered</remapping>
        </ros>
        <num_wheel_pairs>2</num_wheel_pairs>
        <left_joint>front_left_wheel_joint</left_joint>
        <right_joint>front_right_wheel_joint</right_joint>
        <left_joint>rear_left_wheel_joint</left_joint>
        <right_joint>rear_right_wheel_joint</right_joint>
        <wheel_separation>0.271</wheel_separation>
        <wheel_separation>0.271</wheel_separation>
        <wheel_diameter>0.14324</wheel_diameter>
        <wheel_diameter>0.14324</wheel_diameter>
        <updateRate>100</updateRate>
        <max_wheel_acceleration>1.0</max_wheel_acceleration>
        <robot_base_frame>base_footprint</robot_base_frame>
        <publish_odom>1</publish_odom>
        <publish_odom_tf>0</publish_odom_tf>
        <publish_wheel_tf>1</publish_wheel_tf>
        <odometry_frame>odom</odometry_frame>
      </plugin>
      <pose>0 0 0 0 -0 0</pose>
    </model>
    <model name='grey_wall'>
      <static>1</static>
      <link name='link'>
        <pose>0 0 1.4 0 -0 0</pose>
        <collision name='collision'>
          <geometry>
            <box>
              <size>7.5 0.2 2.8</size>
            </box>
          </geometry>
          <max_contacts>10</max_contacts>
          <surface>
            <contact>
              <ode/>
            </contact>
            <bounce/>
            <friction>
              <torsional>
                <ode/>
              </torsional>
              <ode/>
            </friction>
          </surface>
        </collision>
        <visual name='visual'>
          <cast_shadows>0</cast_shadows>
          <geometry>
            <box>
              <size>7.5 0.2 2.8</size>
            </box>
          </geometry>
          <material>
            <script>
              <uri>model://grey_wall/materials/scripts</uri>
              <uri>model://grey_wall/materials/textures</uri>
              <name>vrc/grey_wall</name>
            </script>
          </material>
        </visual>
        <self_collide>0</self_collide>
        <enable_wind>0</enable_wind>
        <kinematic>0</kinematic>
      </link>
      <pose>-2.37902 2.11633 0 0 -0 0</pose>
    </model>
    <model name='grey_wall_0'>
      <static>1</static>
      <link name='link'>
        <pose>0 0 1.4 0 -0 0</pose>
        <collision name='collision'>
          <geometry>
            <box>
              <size>7.5 0.2 2.8</size>
            </box>
          </geometry>
          <max_contacts>10</max_contacts>
          <surface>
            <contact>
              <ode/>
            </contact>
            <bounce/>
            <friction>
              <torsional>
                <ode/>
              </torsional>
              <ode/>
            </friction>
          </surface>
        </collision>
        <visual name='visual'>
          <cast_shadows>0</cast_shadows>
          <geometry>
            <box>
              <size>7.5 0.2 2.8</size>
            </box>
          </geometry>
          <material>
            <script>
              <uri>model://grey_wall/materials/scripts</uri>
              <uri>model://grey_wall/materials/textures</uri>
              <name>vrc/grey_wall</name>
            </script>
          </material>
        </visual>
        <self_collide>0</self_collide>
        <enable_wind>0</enable_wind>
        <kinematic>0</kinematic>
      </link>
      <pose>-1.25342 -5.00541 0 0 -0 0</pose>
    </model>
    <model name='grey_wall_1'>
      <static>1</static>
      <link name='link'>
        <pose>0 0 1.4 0 -0 0</pose>
        <collision name='collision'>
          <geometry>
            <box>
              <size>7.5 0.2 2.8</size>
            </box>
          </geometry>
          <max_contacts>10</max_contacts>
          <surface>
            <contact>
              <ode/>
            </contact>
            <bounce/>
            <friction>
              <torsional>
                <ode/>
              </torsional>
              <ode/>
            </friction>
          </surface>
        </collision>
        <visual name='visual'>
          <cast_shadows>0</cast_shadows>
          <geometry>
            <box>
              <size>7.5 0.2 2.8</size>
            </box>
          </geometry>
          <material>
            <script>
              <uri>model://grey_wall/materials/scripts</uri>
              <uri>model://grey_wall/materials/textures</uri>
              <name>vrc/grey_wall</name>
            </script>
          </material>
        </visual>
        <self_collide>0</self_collide>
        <enable_wind>0</enable_wind>
        <kinematic>0</kinematic>
      </link>
      <pose>-6.96258 0.448582 0 0 -0 0</pose>
    </model>
    <model name='grey_wall_2'>
      <static>1</static>
      <link name='link'>
        <pose>0 0 1.4 0 -0 0</pose>
        <collision name='collision'>
          <geometry>
            <box>
              <size>7.5 0.2 2.8</size>
            </box>
          </geometry>
          <max_contacts>10</max_contacts>
          <surface>
            <contact>
              <ode/>
            </contact>
            <bounce/>
            <friction>
              <torsional>
                <ode/>
              </torsional>
              <ode/>
            </friction>
          </surface>
        </collision>
        <visual name='visual'>
          <cast_shadows>0</cast_shadows>
          <geometry>
            <box>
              <size>7.5 0.2 2.8</size>
            </box>
          </geometry>
          <material>
            <script>
              <uri>model://grey_wall/materials/scripts</uri>
              <uri>model://grey_wall/materials/textures</uri>
              <name>vrc/grey_wall</name>
            </script>
          </material>
        </visual>
        <self_collide>0</self_collide>
        <enable_wind>0</enable_wind>
        <kinematic>0</kinematic>
      </link>
      <pose>5.0577 -1.57837 0 0 -0 0</pose>
    </model>
  </world>
</sdf>
